<robot name="my_robot">
    <link name="base_link">
        <inertial>
            <mass value="10.0"/>
            <origin xyz="0 0 0"/>
            <inertia ixx="0.1" ixy="0.0" ixz="0.0" iyy="0.1" iyz="0.0" izz="0.1"/>
        </inertial>
        <visual>
            <geometry>
                <box size="0.36 0.35 0.2"/>
            </geometry>
            <material name="grey">
                <color rgba="0.3 0.5 0.5 1.0"/>
            </material>
        </visual>
        <collision>
            <geometry>
                <box size="0.36 0.35 0.2"/>
            </geometry>
        </collision>
    </link>
    <link name="front_left_wheel">
        <visual>
            <geometry>
                <cylinder length="0.05" radius="0.1"/>
            </geometry>
            <material name="black">
                <color rgba="0 0 0 1"/>
            </material>
        </visual>
        <collision>
            <geometry>
                <cylinder length="0.05" radius="0.1"/>
            </geometry>
        </collision>
        <inertial>
            <mass value="0.1"/>
            <origin xyz="0 0 0"/>
            <inertia ixx="0.01" ixy="0.0" ixz="0.0" iyy="0.01" iyz="0.0" izz="0.01"/>
        </inertial>
    </link>
    <link name="front_right_wheel">
        <visual>
            <geometry>
                <cylinder length="0.05" radius="0.1"/>
            </geometry>
            <material name="black">
                <color rgba="0 0 0 1"/>
            </material>
        </visual>
        <collision>
            <geometry>
                <cylinder length="0.05" radius="0.1"/>
            </geometry>
        </collision>
        <inertial>
            <mass value="0.1"/>
            <origin xyz="0 0 0"/>
            <inertia ixx="0.01" ixy="0.0" ixz="0.0" iyy="0.01" iyz="0.0" izz="0.01"/>
        </inertial>
    </link>
    <link name="rear_left_wheel">
        <visual>
            <geometry>
                <cylinder length="0.05" radius="0.1"/>
            </geometry>
            <material name="black">
                <color rgba="0 0 0 1"/>
            </material>
        </visual>
        <collision>
            <geometry>
                <cylinder length="0.05" radius="0.1"/>
            </geometry>
        </collision>
        <inertial>
            <mass value="0.1"/>
            <origin xyz="0 0 0"/>
            <inertia ixx="0.01" ixy="0.0" ixz="0.0" iyy="0.01" iyz="0.0" izz="0.01"/>
        </inertial>
    </link>
    <link name="rear_right_wheel">
        <visual>
            <geometry>
                <cylinder length="0.05" radius="0.1"/>
            </geometry>
            <material name="black">
                <color rgba="0 0 0 1"/>
            </material>
        </visual>
        <collision>
            <geometry>
                <cylinder length="0.05" radius="0.1"/>
            </geometry>
        </collision>
        <inertial>
            <mass value="0.1"/>
            <origin xyz="0 0 0"/>
            <inertia ixx="0.01" ixy="0.0" ixz="0.0" iyy="0.01" iyz="0.0" izz="0.01"/>
        </inertial>
    </link>
    <link name="lidar">
        <origin xyz="0 0 0.3"/>
        <sensor type="lidar">
            <update_rate>30</update_rate>
            <range>
                <min>0.1</min>
                <max>10.0</max>
            </range>
            <horizontal>
                <samples>360</samples>
                <resolution>1</resolution>
                <min_angle>1</min_angle>
                <max_angle>360</max_angle>
            </horizontal>
        </sensor>
    </link>
    <joint name="base_to_lidar" type="fixed">
        <parent link="base_link"/>
        <child link="lidar"/>
        <origin xyz="0 0 0.3" rpy="0 0 3.14159"/>
    </joint>
    <joint name="front_left_wheel_joint" type="continuous">
        <parent link="base_link"/>
        <child link="front_left_wheel"/>
        <origin xyz="-0.16 0.145 -0.05" rpy="1.5708 0 0"/>
        <axis xyz="0 0 1"/>
        <dynamics damping="0.04" friction="0.9"/>
    </joint>
    <joint name="front_right_wheel_joint" type="continuous">
        <parent link="base_link"/>
        <child link="front_right_wheel"/>
        <origin xyz="-0.16 -0.145 -0.05" rpy="1.5708 0 0"/>
        <axis xyz="0 0 1"/>
        <dynamics damping="0.04" friction="0.9"/>
    </joint>
    <joint name="rear_left_wheel_joint" type="continuous">
        <parent link="base_link"/>
        <child link="rear_left_wheel"/>
        <origin xyz="0.16 0.145 -0.05" rpy="1.5708 0 0"/>
        <axis xyz="0 0 1"/>
        <dynamics damping="0.04" friction="0.9"/>
    </joint>
    <joint name="rear_right_wheel_joint" type="continuous">
        <parent link="base_link"/>
        <child link="rear_right_wheel"/>
        <origin xyz="0.16 -0.145 -0.05" rpy="1.5708 0 0"/>
        <axis xyz="0 0 1"/>
        <dynamics damping="0.04" friction="0.9"/>
    </joint>
</robot>
